Traceback (most recent call last):
  File "/rds/general/user/hsl121/home/anaconda3/envs/TDS/lib/python3.9/site-packages/pandas/core/indexes/base.py", line 3805, in get_loc
    return self._engine.get_loc(casted_key)
  File "index.pyx", line 167, in pandas._libs.index.IndexEngine.get_loc
  File "index.pyx", line 196, in pandas._libs.index.IndexEngine.get_loc
  File "pandas/_libs/hashtable_class_helper.pxi", line 7081, in pandas._libs.hashtable.PyObjectHashTable.get_item
  File "pandas/_libs/hashtable_class_helper.pxi", line 7089, in pandas._libs.hashtable.PyObjectHashTable.get_item
KeyError: 'adverse_binary'

The above exception was the direct cause of the following exception:

Traceback (most recent call last):
  File "/rds/general/user/hsl121/home/anaconda3/envs/TDS/lib/python3.9/site-packages/pandas/core/frame.py", line 4485, in _set_item_mgr
    loc = self._info_axis.get_loc(key)
  File "/rds/general/user/hsl121/home/anaconda3/envs/TDS/lib/python3.9/site-packages/pandas/core/indexes/base.py", line 3812, in get_loc
    raise KeyError(key) from err
KeyError: 'adverse_binary'

During handling of the above exception, another exception occurred:

Traceback (most recent call last):
  File "/rds/general/user/hsl121/home/hda_project/adverse/adverse.py", line 80, in <module>
    train_combined['adverse_binary'] = y_train.values  # Use .values to avoid index issues
  File "/rds/general/user/hsl121/home/anaconda3/envs/TDS/lib/python3.9/site-packages/pandas/core/frame.py", line 4311, in __setitem__
    self._set_item(key, value)
  File "/rds/general/user/hsl121/home/anaconda3/envs/TDS/lib/python3.9/site-packages/pandas/core/frame.py", line 4538, in _set_item
    self._set_item_mgr(key, value, refs)
  File "/rds/general/user/hsl121/home/anaconda3/envs/TDS/lib/python3.9/site-packages/pandas/core/frame.py", line 4488, in _set_item_mgr
    self._mgr.insert(len(self._info_axis), key, value, refs)
  File "/rds/general/user/hsl121/home/anaconda3/envs/TDS/lib/python3.9/site-packages/pandas/core/internals/managers.py", line 1370, in insert
    raise ValueError(
ValueError: Expected a 1D array, got an array with shape (16461, 2)
