/rds/general/user/hsl121/home/anaconda3/envs/TDS/lib/python3.9/site-packages/joblib/externals/loky/process_executor.py:752: UserWarning: A worker stopped while some jobs were given to the executor. This can be caused by a too short worker timeout or by a memory leak.
  warnings.warn(
Traceback (most recent call last):
  File "/rds/general/user/hsl121/home/anaconda3/envs/TDS/lib/python3.9/site-packages/pandas/core/indexes/base.py", line 3805, in get_loc
    return self._engine.get_loc(casted_key)
  File "index.pyx", line 167, in pandas._libs.index.IndexEngine.get_loc
  File "index.pyx", line 196, in pandas._libs.index.IndexEngine.get_loc
  File "pandas/_libs/hashtable_class_helper.pxi", line 7081, in pandas._libs.hashtable.PyObjectHashTable.get_item
  File "pandas/_libs/hashtable_class_helper.pxi", line 7089, in pandas._libs.hashtable.PyObjectHashTable.get_item
KeyError: 'mean_train_MSE'

The above exception was the direct cause of the following exception:

Traceback (most recent call last):
  File "/rds/general/user/hsl121/home/hda_project/rq1/random_forest.py", line 94, in <module>
    results[f'mean_{split}_MSE']  = -results[f'mean_{split}_MSE']
  File "/rds/general/user/hsl121/home/anaconda3/envs/TDS/lib/python3.9/site-packages/pandas/core/frame.py", line 4102, in __getitem__
    indexer = self.columns.get_loc(key)
  File "/rds/general/user/hsl121/home/anaconda3/envs/TDS/lib/python3.9/site-packages/pandas/core/indexes/base.py", line 3812, in get_loc
    raise KeyError(key) from err
KeyError: 'mean_train_MSE'
